I'm sorry, but an uncaught exception occurred.

While running game code:
  File "game/script.rpy", line 148, in script
    me "Alright alright, I’ll get up"
Exception: Sayer 'me' is not defined.

-- Full Traceback ------------------------------------------------------------

Full traceback:
  File "game/script.rpy", line 148, in script
    me "Alright alright, I’ll get up"
  File "C:\Users\Aka\Desktop\renpy-8.1.0-sdk\renpy\ast.py", line 890, in execute
    who = eval_who(self.who, self.who_fast)
  File "C:\Users\Aka\Desktop\renpy-8.1.0-sdk\renpy\ast.py", line 783, in eval_who
    raise Exception("Sayer '%s' is not defined." % who)
Exception: Sayer 'me' is not defined.

Windows-10-10.0.22621 AMD64
Ren'Py 8.1.0.23051307
Afterlove 1.0
Wed May 31 17:29:10 2023
